<?xml version="1.0"?>
<robot name="pan_tilt">
    <link name="base_link">
        <visual>
            <geometry>
                <cylinder radius="0.2" length="0.01"/>
            </geometry>
            <origin rpy="0 0 0" xyz="0 0 0"/>
            <material name="yellow">
                <color rgba="1 1 0 1"/>
            </material>
        </visual>
        <!-- <collision>
            <geometry>
                <mesh filename="package://pkg_name/meshes/file_name"/>
                <box size="1.0 1.0 1.0" />
                <cylinder radius="1.0" length="1.0"/>
            </geometry>
        </collision>
        <inertial>
            <mass value="0.0"/>
            <origin xyz="0.0 0.0 0.0" rpy="0.0 0.0 0.0"/>
            <inertia ixx="0.0" ixy="0.0" ixz="0.0" iyy="0.0" iyz="0.0" izz="0.0"/>
        </inertial> -->
    </link>
    <joint name="pan_joint" type="revolute">
        <parent link="base_link"/>
        <child link="pan_link"/>
        <origin xyz="0 0 0.1" rpy="0 0 0"/>
        <axis xyz="0 0 1"/>
        <limit effort="300" velocity="0.1" lower="-3.14" upper="3.14"/>
        <dynamics damping="50" friction="1"/>
    </joint>
    <link name="pan_link">
        <visual>
            <geometry>
                <cylinder radius="0.04" length="0.4"/>
            </geometry>
            <material name="red">
                <color rgba="0 0 1.0 1.0"/>
            </material>
        </visual>
        <!-- <collision>
            <geometry>
                <mesh filename="package://pkg_name/meshes/file_name"/>
                <box size="1.0 1.0 1.0" />
                <cylinder radius="1.0" length="1.0"/>
            </geometry>
        </collision>
        <inertial>
            <mass value="0.0"/>
            <origin xyz="0.0 0.0 0.0" rpy="0.0 0.0 0.0"/>
            <inertia ixx="0.0" ixy="0.0" ixz="0.0" iyy="0.0" iyz="0.0" izz="0.0"/>
        </inertial> -->
    </link>
    <joint name="tilt_joint" type="revolute">
        <parent link="pan_link"/>
        <child link="tilt_link"/>
        <origin xyz="0 0 0.2" rpy="0 0 0"/>
        <axis xyz="0 1 0"/>
        <limit effort="300" velocity="0.1" lower="-4.64" upper="-1.5"/>
        <dynamics damping="50" friction="1"/>
    </joint>
    <link name="tilt_link">
        <visual>
            <geometry>
                <cylinder radius="0.04" length="0.4"/>
            </geometry>
            <material name="green">
                <color rgba="1 0 0 1"/>
            </material>
        </visual>
        <!-- <collision>
            <geometry>
                <mesh filename="package://pkg_name/meshes/file_name"/>
                <box size="1.0 1.0 1.0" />
                <cylinder radius="1.0" length="1.0"/>
            </geometry>
        </collision>
        <inertial>
            <mass value="0.0"/>
            <origin xyz="0.0 0.0 0.0" rpy="0.0 0.0 0.0"/>
            <inertia ixx="0.0" ixy="0.0" ixz="0.0" iyy="0.0" iyz="0.0" izz="0.0"/>
        </inertial> -->
    </link>
</robot>
